Workbook

Sheet Continuous Assessment Records
A1: Course Code | B1: Course Name | C1: Assessment Type (Assignment/Unit Test/Mid-Term) | D1: Assessment No. | E1: Question No. | F1: CO Mapped | G1: PO(s) Mapped | H1: PSO(s) Mapped | I1: Bloom’s Level | J1: Max Marks | K1: Obtained Marks | L1: Class Avg % (as 0.00-1.00) | M1: Attainment Level (Auto) | N1: Evidence Link (URL/File)
A2: CSE301 | B2: Data Mining | C2: Assignment | D2: A1 | E2: Q1 | F2: CO1 | G2: PO1, PO2 | H2: PSO1 | I2: Apply | J2: 10 | K2: 8 | L2: 0.75 | M2: =IF(L2="","",IF(L2>=0.7,3,IF(L2>=0.6,2,IF(L2>=0.5,1,0)))) | N2: A1_Q1.pdf
A3: CSE301 | B3: Data Mining | C3: Unit Test | D3: UT1 | E3: Q2 | F3: CO2 | G3: PO3 | H3: PSO2 | I3: Analyze | J3: 15 | K3: 12 | L3: 0.7 | M3: =IF(L3="","",IF(L3>=0.7,3,IF(L3>=0.6,2,IF(L3>=0.5,1,0)))) | N3: UT1_Q2.pdf
A4: CSE301 | B4: Data Mining | C4: Mid-Term | D4: MT1 | E4: Q3 | F4: CO3 | G4: PO4, PO5 | H4: PSO3 | I4: Evaluate | J4: 20 | K4: 14 | L4: 0.65 | M4: =IF(L4="","",IF(L4>=0.7,3,IF(L4>=0.6,2,IF(L4>=0.5,1,0)))) | N4: MT1_Q3.pdf
M5: =IF(L5="","",IF(L5>=0.7,3,IF(L5>=0.6,2,IF(L5>=0.5,1,0))))
M6: =IF(L6="","",IF(L6>=0.7,3,IF(L6>=0.6,2,IF(L6>=0.5,1,0))))
M7: =IF(L7="","",IF(L7>=0.7,3,IF(L7>=0.6,2,IF(L7>=0.5,1,0))))
M8: =IF(L8="","",IF(L8>=0.7,3,IF(L8>=0.6,2,IF(L8>=0.5,1,0))))
M9: =IF(L9="","",IF(L9>=0.7,3,IF(L9>=0.6,2,IF(L9>=0.5,1,0))))
M10: =IF(L10="","",IF(L10>=0.7,3,IF(L10>=0.6,2,IF(L10>=0.5,1,0))))
M11: =IF(L11="","",IF(L11>=0.7,3,IF(L11>=0.6,2,IF(L11>=0.5,1,0))))
M12: =IF(L12="","",IF(L12>=0.7,3,IF(L12>=0.6,2,IF(L12>=0.5,1,0))))
M13: =IF(L13="","",IF(L13>=0.7,3,IF(L13>=0.6,2,IF(L13>=0.5,1,0))))
M14: =IF(L14="","",IF(L14>=0.7,3,IF(L14>=0.6,2,IF(L14>=0.5,1,0))))
M15: =IF(L15="","",IF(L15>=0.7,3,IF(L15>=0.6,2,IF(L15>=0.5,1,0))))
M16: =IF(L16="","",IF(L16>=0.7,3,IF(L16>=0.6,2,IF(L16>=0.5,1,0))))
... M501: =IF(L501="","",IF(L501>=0.7,3,IF(L501>=0.6,2,IF(L501>=0.5,1,0))))

Sheet CO–PO Attainment Summary
A1: Course Code | B1: CO | C1: Assessment Tools (Assignment/UT/MT) | D1: Attainment Level (Direct) | E1: Attainment Level (Indirect - Feedback/Survey) | F1: Final Attainment Level | G1: PO(s) Addressed | H1: PSO(s) Addressed
A2: CSE301 | B2: CO1 | C2: A1, A2 | D2: =IFERROR(AVERAGEIFS('Continuous Assessment Records'!M:M,'Continuous Assessment Records'!A:A,A2,'Continuous Assessment Records'!F:F,B2),"") | F2: =IF(E2="",D2,ROUND(0.8*D2+0.2*E2,0)) | G2: PO1, PO2 | H2: PSO1
A3: CSE301 | B3: CO2 | C3: UT1, UT2 | D3: =IFERROR(AVERAGEIFS('Continuous Assessment Records'!M:M,'Continuous Assessment Records'!A:A,A3,'Continuous Assessment Records'!F:F,B3),"") | F3: =IF(E3="",D3,ROUND(0.8*D3+0.2*E3,0)) | G3: PO3 | H3: PSO2
A4: CSE301 | B4: CO3 | C4: MT1, MT2 | D4: =IFERROR(AVERAGEIFS('Continuous Assessment Records'!M:M,'Continuous Assessment Records'!A:A,A4,'Continuous Assessment Records'!F:F,B4),"") | F4: =IF(E4="",D4,ROUND(0.8*D4+0.2*E4,0)) | G4: PO4, PO5 | H4: PSO3
A5: CSE301 | B5: CO4 | C5: A3, UT2, MT1 | D5: =IFERROR(AVERAGEIFS('Continuous Assessment Records'!M:M,'Continuous Assessment Records'!A:A,A5,'Continuous Assessment Records'!F:F,B5),"") | F5: =IF(E5="",D5,ROUND(0.8*D5+0.2*E5,0)) | G5: PO4, PO5 | H5: PSO2
D6: =IFERROR(AVERAGEIFS('Continuous Assessment Records'!M:M,'Continuous Assessment Records'!A:A,A6,'Continuous Assessment Records'!F:F,B6),"") | F6: =IF(E6="",D6,ROUND(0.8*D6+0.2*E6,0))
D7: =IFERROR(AVERAGEIFS('Continuous Assessment Records'!M:M,'Continuous Assessment Records'!A:A,A7,'Continuous Assessment Records'!F:F,B7),"") | F7: =IF(E7="",D7,ROUND(0.8*D7+0.2*E7,0))
D8: =IFERROR(AVERAGEIFS('Continuous Assessment Records'!M:M,'Continuous Assessment Records'!A:A,A8,'Continuous Assessment Records'!F:F,B8),"") | F8: =IF(E8="",D8,ROUND(0.8*D8+0.2*E8,0))
D9: =IFERROR(AVERAGEIFS('Continuous Assessment Records'!M:M,'Continuous Assessment Records'!A:A,A9,'Continuous Assessment Records'!F:F,B9),"") | F9: =IF(E9="",D9,ROUND(0.8*D9+0.2*E9,0))
D10: =IFERROR(AVERAGEIFS('Continuous Assessment Records'!M:M,'Continuous Assessment Records'!A:A,A10,'Continuous Assessment Records'!F:F,B10),"") | F10: =IF(E10="",D10,ROUND(0.8*D10+0.2*E10,0))
D11: =IFERROR(AVERAGEIFS('Continuous Assessment Records'!M:M,'Continuous Assessment Records'!A:A,A11,'Continuous Assessment Records'!F:F,B11),"") | F11: =IF(E11="",D11,ROUND(0.8*D11+0.2*E11,0))
D12: =IFERROR(AVERAGEIFS('Continuous Assessment Records'!M:M,'Continuous Assessment Records'!A:A,A12,'Continuous Assessment Records'!F:F,B12),"") | F12: =IF(E12="",D12,ROUND(0.8*D12+0.2*E12,0))
D13: =IFERROR(AVERAGEIFS('Continuous Assessment Records'!M:M,'Continuous Assessment Records'!A:A,A13,'Continuous Assessment Records'!F:F,B13),"") | F13: =IF(E13="",D13,ROUND(0.8*D13+0.2*E13,0))
D14: =IFERROR(AVERAGEIFS('Continuous Assessment Records'!M:M,'Continuous Assessment Records'!A:A,A14,'Continuous Assessment Records'!F:F,B14),"") | F14: =IF(E14="",D14,ROUND(0.8*D14+0.2*E14,0))
D15: =IFERROR(AVERAGEIFS('Continuous Assessment Records'!M:M,'Continuous Assessment Records'!A:A,A15,'Continuous Assessment Records'!F:F,B15),"") | F15: =IF(E15="",D15,ROUND(0.8*D15+0.2*E15,0))
D16: =IFERROR(AVERAGEIFS('Continuous Assessment Records'!M:M,'Continuous Assessment Records'!A:A,A16,'Continuous Assessment Records'!F:F,B16),"") | F16: =IF(E16="",D16,ROUND(0.8*D16+0.2*E16,0))
D17: =IFERROR(AVERAGEIFS('Continuous Assessment Records'!M:M,'Continuous Assessment Records'!A:A,A17,'Continuous Assessment Records'!F:F,B17),"") | F17: =IF(E17="",D17,ROUND(0.8*D17+0.2*E17,0))
... D101: =IFERROR(AVERAGEIFS('Continuous Assessment Records'!M:M,'Continuous Assessment Records'!A:A,A101,'Continuous Assessment Records'!F:F,B101),"") | F101: =IF(E101="",D101,ROUND(0.8*D101+0.2*E101,0))

Sheet Evidence Tracker
A1: Course Code | B1: Assessment Type | C1: Assessment No. | D1: Document/File Name | E1: Evidence Link (Drive/SharePoint/Folder) | F1: Verified (Y/N)
A2: CSE301 | B2: Assignment | C2: A1 | D2: A1_Q1.pdf | E2: https://drive.google.com/… | F2: Y
A3: CSE301 | B3: Unit Test | C3: UT1 | D3: UT1_Q2.pdf | E3: https://drive.google.com/… | F3: Y
A4: CSE301 | B4: Mid-Term | C4: MT1 | D4: MT1_Q3.pdf | E4: https://drive.google.com/… | F4: Y

Sheet README
A1: Continuous Assessment Mapping — How to Use
A2: 1) Enter records in 'Continuous Assessment Records' (rows 2..500). Keep Class Avg as a decimal (e.g., 0.72 = 72%).
A3: 2) Attainment Level (Auto) uses thresholds: ≥70% → 3, ≥60% → 2, ≥50% → 1, else 0.
A4: 3) 'CO–PO Attainment Summary' and 'CO Attainment Analysis' auto-pull attainment. Enter Indirect Attainment where applicable.
A5: 4) Use 'Assignment/UT/Mid-Term Mapping' sheets to maintain CO links and evidence for NBA.
A6: 5) 'PO_PSO Aggregation' computes program-level attainment via CO Final × Mapping Strengths.
A7: 6) Adjust weights in analysis/summary sheets as per departmental policy.

Sheet Assignment Mapping
A1: Course Code | B1: Course Name | C1: Assignment No. | D1: Topic / Question | E1: Bloom’s Taxonomy Level | F1: CO Mapped | G1: PO(s) Mapped | H1: PSO(s) Mapped | I1: Weightage (%) | J1: Attainment Level (0–3) | K1: Evidence (File/Link)
A2: CSE301 | B2: Data Mining | C2: A1 | D2: Implement Apriori algorithm for market basket analysis | E2: Apply | F2: CO1 | G2: PO1, PO2 | H2: PSO1 | I2: 10 | J2: 2 | K2: A1_Solution.pdf
A3: CSE301 | B3: Data Mining | C3: A2 | D3: Review clustering algorithms and applications in big data | E3: Analyze | F3: CO2 | G3: PO3 | H3: PSO2 | I3: 15 | J3: 2 | K3: A2_Report.pdf
A4: CSE301 | B4: Data Mining | C4: A3 | D4: Design and evaluate a recommender system | E4: Create | F4: CO3 | G4: PO4, PO5 | H4: PSO3 | I4: 20 | J4: 3 | K4: A3_Project.zip

Sheet Unit Test Mapping
A1: Course Code | B1: Course Name | C1: Unit Test No. (UT1/UT2/…) | D1: Q. No. | E1: Question | F1: Marks | G1: CO Mapped | H1: PO(s) Mapped | I1: PSO(s) Mapped | J1: Bloom’s Level | K1: Difficulty (L/M/H) | L1: Evidence Link (PDF/Folder)
A2: CSE301 | B2: Data Mining | C2: UT1 | D2: 1(a) | E2: Define data mining and list applications | F2: 4 | G2: CO1 | H2: PO1 | I2: PSO1 | J2: Remember/Understand | K2: L | L2: UT1_Q1a.pdf
A3: CSE301 | B3: Data Mining | C3: UT1 | D3: 1(b) | E3: Differentiate classification vs clustering with examples | F3: 6 | G3: CO2 | H3: PO2, PO3 | I3: PSO2 | J3: Analyze | K3: M | L3: UT1_Q1b.pdf
A4: CSE301 | B4: Data Mining | C4: UT1 | D4: 2 | E4: Apply Apriori algorithm to the given dataset | F4: 10 | G4: CO3 | H4: PO1, PO4 | I4: PSO1 | J4: Apply | K4: H | L4: UT1_Q2.pdf
A5: CSE301 | B5: Data Mining | C5: UT1 | D5: 3 | E5: Evaluate k-means using silhouette score on sample data | F5: 10 | G5: CO4 | H5: PO4, PO5 | I5: PSO3 | J5: Evaluate | K5: H | L5: UT1_Q3.pdf

Sheet Mid-Term Mapping
A1: Course Code | B1: Course Name | C1: Mid-Term No. (MT1/MT2/…) | D1: Q. No. | E1: Question | F1: Marks | G1: CO Mapped | H1: PO(s) Mapped | I1: PSO(s) Mapped | J1: Bloom’s Level | K1: Difficulty (L/M/H) | L1: Evaluation Criteria / Rubric | M1: Evidence Link (PDF/Folder)
A2: CSE301 | B2: Data Mining | C2: MT1 | D2: 1(a) | E2: Explain types of data preprocessing | F2: 5 | G2: CO1 | H2: PO1 | I2: PSO1 | J2: Understand | K2: L | L2: Correctness, clarity | M2: MT1_Q1a.pdf
A3: CSE301 | B3: Data Mining | C3: MT1 | D3: 1(b) | E3: Apply decision tree algorithm to dataset | F3: 10 | G3: CO2 | H3: PO2, PO3 | I3: PSO2 | J3: Apply | K3: M | L3: Application, logic clarity | M3: MT1_Q1b.pdf
A4: CSE301 | B4: Data Mining | C4: MT1 | D4: 2 | E4: Analyze Naïve Bayes vs SVM performance | F4: 15 | G4: CO3 | H4: PO4 | I4: PSO2 | J4: Analyze | K4: H | L4: Analytical depth, evidence | M4: MT1_Q2.pdf
A5: CSE301 | B5: Data Mining | C5: MT1 | D5: 3 | E5: Design a neural network model for classification | F5: 20 | G5: CO4 | H5: PO5 | I5: PSO3 | J5: Create | K5: H | L5: Innovation, feasibility | M5: MT1_Q3.pdf

Sheet Attendance & Marks Register
A1: Course Code | B1: Course Name | C1: Semester/Section | D1: Roll No. | E1: Student Name | F1: Total Classes Conducted | G1: Classes Attended | H1: Attendance % (Auto) | I1: Assignment Marks (20) | J1: Unit Test Marks (30) | K1: Mid-Term Marks (50) | L1: Total (100) (Auto) | M1: Overall % (Auto) | N1: CO Attainment Level (0–3) (Auto)
A2: CSE301 | B2: Data Mining | C2: Sem V - A | D2: 101 | E2: A. Kumar | F2: 40 | G2: 38 | H2: =IF(F2=0,"",IFERROR(G2/F2, "")) | I2: 18 | J2: 24 | K2: 42 | L2: =IF(COUNTA(I2:K2)=3, I2+J2+K2, "") | M2: =IF(L2="","",L2/100) | N2: =IF(M2="","",IF(M2>=0.7,3,IF(M2>=0.6,2,IF(M2>=0.5,1,0))))
A3: CSE301 | B3: Data Mining | C3: Sem V - A | D3: 102 | E3: B. Singh | F3: 40 | G3: 28 | H3: =IF(F3=0,"",IFERROR(G3/F3, "")) | I3: 12 | J3: 18 | K3: 30 | L3: =IF(COUNTA(I3:K3)=3, I3+J3+K3, "") | M3: =IF(L3="","",L3/100) | N3: =IF(M3="","",IF(M3>=0.7,3,IF(M3>=0.6,2,IF(M3>=0.5,1,0))))
A4: CSE301 | B4: Data Mining | C4: Sem V - A | D4: 103 | E4: C. Rao | F4: 40 | G4: 20 | H4: =IF(F4=0,"",IFERROR(G4/F4, "")) | I4: 8 | J4: 12 | K4: 22 | L4: =IF(COUNTA(I4:K4)=3, I4+J4+K4, "") | M4: =IF(L4="","",L4/100) | N4: =IF(M4="","",IF(M4>=0.7,3,IF(M4>=0.6,2,IF(M4>=0.5,1,0))))
H5: =IF(F5=0,"",IFERROR(G5/F5, "")) | L5: =IF(COUNTA(I5:K5)=3, I5+J5+K5, "") | M5: =IF(L5="","",L5/100) | N5: =IF(M5="","",IF(M5>=0.7,3,IF(M5>=0.6,2,IF(M5>=0.5,1,0))))
H6: =IF(F6=0,"",IFERROR(G6/F6, "")) | L6: =IF(COUNTA(I6:K6)=3, I6+J6+K6, "") | M6: =IF(L6="","",L6/100) | N6: =IF(M6="","",IF(M6>=0.7,3,IF(M6>=0.6,2,IF(M6>=0.5,1,0))))
H7: =IF(F7=0,"",IFERROR(G7/F7, "")) | L7: =IF(COUNTA(I7:K7)=3, I7+J7+K7, "") | M7: =IF(L7="","",L7/100) | N7: =IF(M7="","",IF(M7>=0.7,3,IF(M7>=0.6,2,IF(M7>=0.5,1,0))))
H8: =IF(F8=0,"",IFERROR(G8/F8, "")) | L8: =IF(COUNTA(I8:K8)=3, I8+J8+K8, "") | M8: =IF(L8="","",L8/100) | N8: =IF(M8="","",IF(M8>=0.7,3,IF(M8>=0.6,2,IF(M8>=0.5,1,0))))
H9: =IF(F9=0,"",IFERROR(G9/F9, "")) | L9: =IF(COUNTA(I9:K9)=3, I9+J9+K9, "") | M9: =IF(L9="","",L9/100) | N9: =IF(M9="","",IF(M9>=0.7,3,IF(M9>=0.6,2,IF(M9>=0.5,1,0))))
H10: =IF(F10=0,"",IFERROR(G10/F10, "")) | L10: =IF(COUNTA(I10:K10)=3, I10+J10+K10, "") | M10: =IF(L10="","",L10/100) | N10: =IF(M10="","",IF(M10>=0.7,3,IF(M10>=0.6,2,IF(M10>=0.5,1,0))))
H11: =IF(F11=0,"",IFERROR(G11/F11, "")) | L11: =IF(COUNTA(I11:K11)=3, I11+J11+K11, "") | M11: =IF(L11="","",L11/100) | N11: =IF(M11="","",IF(M11>=0.7,3,IF(M11>=0.6,2,IF(M11>=0.5,1,0))))
H12: =IF(F12=0,"",IFERROR(G12/F12, "")) | L12: =IF(COUNTA(I12:K12)=3, I12+J12+K12, "") | M12: =IF(L12="","",L12/100) | N12: =IF(M12="","",IF(M12>=0.7,3,IF(M12>=0.6,2,IF(M12>=0.5,1,0))))
H13: =IF(F13=0,"",IFERROR(G13/F13, "")) | L13: =IF(COUNTA(I13:K13)=3, I13+J13+K13, "") | M13: =IF(L13="","",L13/100) | N13: =IF(M13="","",IF(M13>=0.7,3,IF(M13>=0.6,2,IF(M13>=0.5,1,0))))
H14: =IF(F14=0,"",IFERROR(G14/F14, "")) | L14: =IF(COUNTA(I14:K14)=3, I14+J14+K14, "") | M14: =IF(L14="","",L14/100) | N14: =IF(M14="","",IF(M14>=0.7,3,IF(M14>=0.6,2,IF(M14>=0.5,1,0))))
H15: =IF(F15=0,"",IFERROR(G15/F15, "")) | L15: =IF(COUNTA(I15:K15)=3, I15+J15+K15, "") | M15: =IF(L15="","",L15/100) | N15: =IF(M15="","",IF(M15>=0.7,3,IF(M15>=0.6,2,IF(M15>=0.5,1,0))))
H16: =IF(F16=0,"",IFERROR(G16/F16, "")) | L16: =IF(COUNTA(I16:K16)=3, I16+J16+K16, "") | M16: =IF(L16="","",L16/100) | N16: =IF(M16="","",IF(M16>=0.7,3,IF(M16>=0.6,2,IF(M16>=0.5,1,0))))
... H202: =IF(F202=0,"",IFERROR(G202/F202, "")) | L202: =IF(COUNTA(I202:K202)=3, I202+J202+K202, "") | M202: =IF(L202="","",L202/100) | N202: =IF(M202="","",IF(M202>=0.7,3,IF(M202>=0.6,2,IF(M202>=0.5,1,0))))

Sheet Rubrics & Answer Scripts
A1: Course Code | B1: Course Name | C1: Assessment Type (Assignment/UT/MT/Project) | D1: Assessment No. | E1: Question No. | F1: Criteria | G1: Max Marks | H1: Marks Awarded | I1: Attainment Level (0–3) | J1: Evidence Link (Scanned Script/Folder)
A2: CSE301 | B2: Data Mining | C2: Assignment | D2: A1 | E2: Q1 | F2: Understanding & Concepts | G2: 5 | H2: 4 | I2: 2 | J2: A1_Q1_Script_High.pdf
A3: CSE301 | B3: Data Mining | C3: Assignment | D3: A1 | E3: Q1 | F3: Application of Knowledge | G3: 5 | H3: 3 | I3: 2 | J3: A1_Q1_Script_High.pdf
A4: CSE301 | B4: Data Mining | C4: Unit Test | D4: UT1 | E4: Q2 | F4: Analysis & Problem Solving | G4: 10 | H4: 7 | I4: 2 | J4: UT1_Q2_Script_Medium.pdf
A5: CSE301 | B5: Data Mining | C5: Mid-Term | D5: MT1 | E5: Q3 | F5: Design & Innovation | G5: 15 | H5: 10 | I5: 2 | J5: MT1_Q3_Script_Low.pdf

Sheet CO Attainment Analysis
A1: Avg % – Assignments (Auto) | B1: Avg % – Unit Tests (Auto) | C1: Avg % – Mid-Terms (Auto) | D1: Weighted Avg % (Auto) | E1: Direct Attainment Level (0–3) (Auto) | F1: Indirect Attainment Level (Auto) | G1: Final Attainment Level (0–3) (Auto) | H1: PSO(s) Addressed (Auto) | I1: Avg % – Assignments (Auto) | J1: Avg % – Unit Tests (Auto) | K1: Avg % – Mid-Terms (Auto) | L1: Weighted Avg % (Auto) | M1: Direct Attainment Level (0–3) (Auto) | N1: Indirect Attainment Level (Auto) | O1: Final Attainment Level (0–3) (Auto)
A2: ='CO–PO Attainment Summary'!A2 | B2: ='CO–PO Attainment Summary'!B2 | C2: ='CO–PO Attainment Summary'!C2 | D2: ='CO–PO Attainment Summary'!D2 | E2: ='CO–PO Attainment Summary'!E2 | F2: ='CO–PO Attainment Summary'!F2 | G2: ='CO–PO Attainment Summary'!G2 | H2: ='CO–PO Attainment Summary'!H2 | I2: =IFERROR(AVERAGEIFS('Continuous Assessment Records'!L:L,'Continuous Assessment Records'!A:A,$A2,'Continuous Assessment Records'!F:F,$B2,'Continuous Assessment Records'!C:C,"Assignment"),"") | J2: =IFERROR(AVERAGEIFS('Continuous Assessment Records'!L:L,'Continuous Assessment Records'!A:A,$A2,'Continuous Assessment Records'!F:F,$B2,'Continuous Assessment Records'!C:C,"Unit Test"),"") | K2: =IFERROR(AVERAGEIFS('Continuous Assessment Records'!L:L,'Continuous Assessment Records'!A:A,$A2,'Continuous Assessment Records'!F:F,$B2,'Continuous Assessment Records'!C:C,"Mid-Term"),"") | L2: =IF(OR(I2="",J2="",K2=""),"",I2*$I$205+J2*$J$205+K2*$K$205) | M2: =IF(L2="","",IF(L2>=0.7,3,IF(L2>=0.6,2,IF(L2>=0.5,1,0)))) | N2: ='CO–PO Attainment Summary'!E2 | O2: =IF(M2="",'CO–PO Attainment Summary'!F2,ROUND(0.8*M2+0.2*N2,0))
A3: ='CO–PO Attainment Summary'!A3 | B3: ='CO–PO Attainment Summary'!B3 | C3: ='CO–PO Attainment Summary'!C3 | D3: ='CO–PO Attainment Summary'!D3 | E3: ='CO–PO Attainment Summary'!E3 | F3: ='CO–PO Attainment Summary'!F3 | G3: ='CO–PO Attainment Summary'!G3 | H3: ='CO–PO Attainment Summary'!H3 | I3: =IFERROR(AVERAGEIFS('Continuous Assessment Records'!L:L,'Continuous Assessment Records'!A:A,$A3,'Continuous Assessment Records'!F:F,$B3,'Continuous Assessment Records'!C:C,"Assignment"),"") | J3: =IFERROR(AVERAGEIFS('Continuous Assessment Records'!L:L,'Continuous Assessment Records'!A:A,$A3,'Continuous Assessment Records'!F:F,$B3,'Continuous Assessment Records'!C:C,"Unit Test"),"") | K3: =IFERROR(AVERAGEIFS('Continuous Assessment Records'!L:L,'Continuous Assessment Records'!A:A,$A3,'Continuous Assessment Records'!F:F,$B3,'Continuous Assessment Records'!C:C,"Mid-Term"),"") | L3: =IF(OR(I3="",J3="",K3=""),"",I3*$I$205+J3*$J$205+K3*$K$205) | M3: =IF(L3="","",IF(L3>=0.7,3,IF(L3>=0.6,2,IF(L3>=0.5,1,0)))) | N3: ='CO–PO Attainment Summary'!E3 | O3: =IF(M3="",'CO–PO Attainment Summary'!F3,ROUND(0.8*M3+0.2*N3,0))
A4: ='CO–PO Attainment Summary'!A4 | B4: ='CO–PO Attainment Summary'!B4 | C4: ='CO–PO Attainment Summary'!C4 | D4: ='CO–PO Attainment Summary'!D4 | E4: ='CO–PO Attainment Summary'!E4 | F4: ='CO–PO Attainment Summary'!F4 | G4: ='CO–PO Attainment Summary'!G4 | H4: ='CO–PO Attainment Summary'!H4 | I4: =IFERROR(AVERAGEIFS('Continuous Assessment Records'!L:L,'Continuous Assessment Records'!A:A,$A4,'Continuous Assessment Records'!F:F,$B4,'Continuous Assessment Records'!C:C,"Assignment"),"") | J4: =IFERROR(AVERAGEIFS('Continuous Assessment Records'!L:L,'Continuous Assessment Records'!A:A,$A4,'Continuous Assessment Records'!F:F,$B4,'Continuous Assessment Records'!C:C,"Unit Test"),"") | K4: =IFERROR(AVERAGEIFS('Continuous Assessment Records'!L:L,'Continuous Assessment Records'!A:A,$A4,'Continuous Assessment Records'!F:F,$B4,'Continuous Assessment Records'!C:C,"Mid-Term"),"") | L4: =IF(OR(I4="",J4="",K4=""),"",I4*$I$205+J4*$J$205+K4*$K$205) | M4: =IF(L4="","",IF(L4>=0.7,3,IF(L4>=0.6,2,IF(L4>=0.5,1,0)))) | N4: ='CO–PO Attainment Summary'!E4 | O4: =IF(M4="",'CO–PO Attainment Summary'!F4,ROUND(0.8*M4+0.2*N4,0))
A5: ='CO–PO Attainment Summary'!A5 | B5: ='CO–PO Attainment Summary'!B5 | C5: ='CO–PO Attainment Summary'!C5 | D5: ='CO–PO Attainment Summary'!D5 | E5: ='CO–PO Attainment Summary'!E5 | F5: ='CO–PO Attainment Summary'!F5 | G5: ='CO–PO Attainment Summary'!G5 | H5: ='CO–PO Attainment Summary'!H5 | I5: =IFERROR(AVERAGEIFS('Continuous Assessment Records'!L:L,'Continuous Assessment Records'!A:A,$A5,'Continuous Assessment Records'!F:F,$B5,'Continuous Assessment Records'!C:C,"Assignment"),"") | J5: =IFERROR(AVERAGEIFS('Continuous Assessment Records'!L:L,'Continuous Assessment Records'!A:A,$A5,'Continuous Assessment Records'!F:F,$B5,'Continuous Assessment Records'!C:C,"Unit Test"),"") | K5: =IFERROR(AVERAGEIFS('Continuous Assessment Records'!L:L,'Continuous Assessment Records'!A:A,$A5,'Continuous Assessment Records'!F:F,$B5,'Continuous Assessment Records'!C:C,"Mid-Term"),"") | L5: =IF(OR(I5="",J5="",K5=""),"",I5*$I$205+J5*$J$205+K5*$K$205) | M5: =IF(L5="","",IF(L5>=0.7,3,IF(L5>=0.6,2,IF(L5>=0.5,1,0)))) | N5: ='CO–PO Attainment Summary'!E5 | O5: =IF(M5="",'CO–PO Attainment Summary'!F5,ROUND(0.8*M5+0.2*N5,0))
A6: ='CO–PO Attainment Summary'!A6 | B6: ='CO–PO Attainment Summary'!B6 | C6: ='CO–PO Attainment Summary'!C6 | D6: ='CO–PO Attainment Summary'!D6 | E6: ='CO–PO Attainment Summary'!E6 | F6: ='CO–PO Attainment Summary'!F6 | G6: ='CO–PO Attainment Summary'!G6 | H6: ='CO–PO Attainment Summary'!H6 | I6: =IFERROR(AVERAGEIFS('Continuous Assessment Records'!L:L,'Continuous Assessment Records'!A:A,$A6,'Continuous Assessment Records'!F:F,$B6,'Continuous Assessment Records'!C:C,"Assignment"),"") | J6: =IFERROR(AVERAGEIFS('Continuous Assessment Records'!L:L,'Continuous Assessment Records'!A:A,$A6,'Continuous Assessment Records'!F:F,$B6,'Continuous Assessment Records'!C:C,"Unit Test"),"") | K6: =IFERROR(AVERAGEIFS('Continuous Assessment Records'!L:L,'Continuous Assessment Records'!A:A,$A6,'Continuous Assessment Records'!F:F,$B6,'Continuous Assessment Records'!C:C,"Mid-Term"),"") | L6: =IF(OR(I6="",J6="",K6=""),"",I6*$I$205+J6*$J$205+K6*$K$205) | M6: =IF(L6="","",IF(L6>=0.7,3,IF(L6>=0.6,2,IF(L6>=0.5,1,0)))) | N6: ='CO–PO Attainment Summary'!E6 | O6: =IF(M6="",'CO–PO Attainment Summary'!F6,ROUND(0.8*M6+0.2*N6,0))
A7: ='CO–PO Attainment Summary'!A7 | B7: ='CO–PO Attainment Summary'!B7 | C7: ='CO–PO Attainment Summary'!C7 | D7: ='CO–PO Attainment Summary'!D7 | E7: ='CO–PO Attainment Summary'!E7 | F7: ='CO–PO Attainment Summary'!F7 | G7: ='CO–PO Attainment Summary'!G7 | H7: ='CO–PO Attainment Summary'!H7 | I7: =IFERROR(AVERAGEIFS('Continuous Assessment Records'!L:L,'Continuous Assessment Records'!A:A,$A7,'Continuous Assessment Records'!F:F,$B7,'Continuous Assessment Records'!C:C,"Assignment"),"") | J7: =IFERROR(AVERAGEIFS('Continuous Assessment Records'!L:L,'Continuous Assessment Records'!A:A,$A7,'Continuous Assessment Records'!F:F,$B7,'Continuous Assessment Records'!C:C,"Unit Test"),"") | K7: =IFERROR(AVERAGEIFS('Continuous Assessment Records'!L:L,'Continuous Assessment Records'!A:A,$A7,'Continuous Assessment Records'!F:F,$B7,'Continuous Assessment Records'!C:C,"Mid-Term"),"") | L7: =IF(OR(I7="",J7="",K7=""),"",I7*$I$205+J7*$J$205+K7*$K$205) | M7: =IF(L7="","",IF(L7>=0.7,3,IF(L7>=0.6,2,IF(L7>=0.5,1,0)))) | N7: ='CO–PO Attainment Summary'!E7 | O7: =IF(M7="",'CO–PO Attainment Summary'!F7,ROUND(0.8*M7+0.2*N7,0))
A8: ='CO–PO Attainment Summary'!A8 | B8: ='CO–PO Attainment Summary'!B8 | C8: ='CO–PO Attainment Summary'!C8 | D8: ='CO–PO Attainment Summary'!D8 | E8: ='CO–PO Attainment Summary'!E8 | F8: ='CO–PO Attainment Summary'!F8 | G8: ='CO–PO Attainment Summary'!G8 | H8: ='CO–PO Attainment Summary'!H8 | I8: =IFERROR(AVERAGEIFS('Continuous Assessment Records'!L:L,'Continuous Assessment Records'!A:A,$A8,'Continuous Assessment Records'!F:F,$B8,'Continuous Assessment Records'!C:C,"Assignment"),"") | J8: =IFERROR(AVERAGEIFS('Continuous Assessment Records'!L:L,'Continuous Assessment Records'!A:A,$A8,'Continuous Assessment Records'!F:F,$B8,'Continuous Assessment Records'!C:C,"Unit Test"),"") | K8: =IFERROR(AVERAGEIFS('Continuous Assessment Records'!L:L,'Continuous Assessment Records'!A:A,$A8,'Continuous Assessment Records'!F:F,$B8,'Continuous Assessment Records'!C:C,"Mid-Term"),"") | L8: =IF(OR(I8="",J8="",K8=""),"",I8*$I$205+J8*$J$205+K8*$K$205) | M8: =IF(L8="","",IF(L8>=0.7,3,IF(L8>=0.6,2,IF(L8>=0.5,1,0)))) | N8: ='CO–PO Attainment Summary'!E8 | O8: =IF(M8="",'CO–PO Attainment Summary'!F8,ROUND(0.8*M8+0.2*N8,0))
A9: ='CO–PO Attainment Summary'!A9 | B9: ='CO–PO Attainment Summary'!B9 | C9: ='CO–PO Attainment Summary'!C9 | D9: ='CO–PO Attainment Summary'!D9 | E9: ='CO–PO Attainment Summary'!E9 | F9: ='CO–PO Attainment Summary'!F9 | G9: ='CO–PO Attainment Summary'!G9 | H9: ='CO–PO Attainment Summary'!H9 | I9: =IFERROR(AVERAGEIFS('Continuous Assessment Records'!L:L,'Continuous Assessment Records'!A:A,$A9,'Continuous Assessment Records'!F:F,$B9,'Continuous Assessment Records'!C:C,"Assignment"),"") | J9: =IFERROR(AVERAGEIFS('Continuous Assessment Records'!L:L,'Continuous Assessment Records'!A:A,$A9,'Continuous Assessment Records'!F:F,$B9,'Continuous Assessment Records'!C:C,"Unit Test"),"") | K9: =IFERROR(AVERAGEIFS('Continuous Assessment Records'!L:L,'Continuous Assessment Records'!A:A,$A9,'Continuous Assessment Records'!F:F,$B9,'Continuous Assessment Records'!C:C,"Mid-Term"),"") | L9: =IF(OR(I9="",J9="",K9=""),"",I9*$I$205+J9*$J$205+K9*$K$205) | M9: =IF(L9="","",IF(L9>=0.7,3,IF(L9>=0.6,2,IF(L9>=0.5,1,0)))) | N9: ='CO–PO Attainment Summary'!E9 | O9: =IF(M9="",'CO–PO Attainment Summary'!F9,ROUND(0.8*M9+0.2*N9,0))
A10: ='CO–PO Attainment Summary'!A10 | B10: ='CO–PO Attainment Summary'!B10 | C10: ='CO–PO Attainment Summary'!C10 | D10: ='CO–PO Attainment Summary'!D10 | E10: ='CO–PO Attainment Summary'!E10 | F10: ='CO–PO Attainment Summary'!F10 | G10: ='CO–PO Attainment Summary'!G10 | H10: ='CO–PO Attainment Summary'!H10 | I10: =IFERROR(AVERAGEIFS('Continuous Assessment Records'!L:L,'Continuous Assessment Records'!A:A,$A10,'Continuous Assessment Records'!F:F,$B10,'Continuous Assessment Records'!C:C,"Assignment"),"") | J10: =IFERROR(AVERAGEIFS('Continuous Assessment Records'!L:L,'Continuous Assessment Records'!A:A,$A10,'Continuous Assessment Records'!F:F,$B10,'Continuous Assessment Records'!C:C,"Unit Test"),"") | K10: =IFERROR(AVERAGEIFS('Continuous Assessment Records'!L:L,'Continuous Assessment Records'!A:A,$A10,'Continuous Assessment Records'!F:F,$B10,'Continuous Assessment Records'!C:C,"Mid-Term"),"") | L10: =IF(OR(I10="",J10="",K10=""),"",I10*$I$205+J10*$J$205+K10*$K$205) | M10: =IF(L10="","",IF(L10>=0.7,3,IF(L10>=0.6,2,IF(L10>=0.5,1,0)))) | N10: ='CO–PO Attainment Summary'!E10 | O10: =IF(M10="",'CO–PO Attainment Summary'!F10,ROUND(0.8*M10+0.2*N10,0))
A11: ='CO–PO Attainment Summary'!A11 | B11: ='CO–PO Attainment Summary'!B11 | C11: ='CO–PO Attainment Summary'!C11 | D11: ='CO–PO Attainment Summary'!D11 | E11: ='CO–PO Attainment Summary'!E11 | F11: ='CO–PO Attainment Summary'!F11 | G11: ='CO–PO Attainment Summary'!G11 | H11: ='CO–PO Attainment Summary'!H11 | I11: =IFERROR(AVERAGEIFS('Continuous Assessment Records'!L:L,'Continuous Assessment Records'!A:A,$A11,'Continuous Assessment Records'!F:F,$B11,'Continuous Assessment Records'!C:C,"Assignment"),"") | J11: =IFERROR(AVERAGEIFS('Continuous Assessment Records'!L:L,'Continuous Assessment Records'!A:A,$A11,'Continuous Assessment Records'!F:F,$B11,'Continuous Assessment Records'!C:C,"Unit Test"),"") | K11: =IFERROR(AVERAGEIFS('Continuous Assessment Records'!L:L,'Continuous Assessment Records'!A:A,$A11,'Continuous Assessment Records'!F:F,$B11,'Continuous Assessment Records'!C:C,"Mid-Term"),"") | L11: =IF(OR(I11="",J11="",K11=""),"",I11*$I$205+J11*$J$205+K11*$K$205) | M11: =IF(L11="","",IF(L11>=0.7,3,IF(L11>=0.6,2,IF(L11>=0.5,1,0)))) | N11: ='CO–PO Attainment Summary'!E11 | O11: =IF(M11="",'CO–PO Attainment Summary'!F11,ROUND(0.8*M11+0.2*N11,0))
A12: ='CO–PO Attainment Summary'!A12 | B12: ='CO–PO Attainment Summary'!B12 | C12: ='CO–PO Attainment Summary'!C12 | D12: ='CO–PO Attainment Summary'!D12 | E12: ='CO–PO Attainment Summary'!E12 | F12: ='CO–PO Attainment Summary'!F12 | G12: ='CO–PO Attainment Summary'!G12 | H12: ='CO–PO Attainment Summary'!H12 | I12: =IFERROR(AVERAGEIFS('Continuous Assessment Records'!L:L,'Continuous Assessment Records'!A:A,$A12,'Continuous Assessment Records'!F:F,$B12,'Continuous Assessment Records'!C:C,"Assignment"),"") | J12: =IFERROR(AVERAGEIFS('Continuous Assessment Records'!L:L,'Continuous Assessment Records'!A:A,$A12,'Continuous Assessment Records'!F:F,$B12,'Continuous Assessment Records'!C:C,"Unit Test"),"") | K12: =IFERROR(AVERAGEIFS('Continuous Assessment Records'!L:L,'Continuous Assessment Records'!A:A,$A12,'Continuous Assessment Records'!F:F,$B12,'Continuous Assessment Records'!C:C,"Mid-Term"),"") | L12: =IF(OR(I12="",J12="",K12=""),"",I12*$I$205+J12*$J$205+K12*$K$205) | M12: =IF(L12="","",IF(L12>=0.7,3,IF(L12>=0.6,2,IF(L12>=0.5,1,0)))) | N12: ='CO–PO Attainment Summary'!E12 | O12: =IF(M12="",'CO–PO Attainment Summary'!F12,ROUND(0.8*M12+0.2*N12,0))
A13: ='CO–PO Attainment Summary'!A13 | B13: ='CO–PO Attainment Summary'!B13 | C13: ='CO–PO Attainment Summary'!C13 | D13: ='CO–PO Attainment Summary'!D13 | E13: ='CO–PO Attainment Summary'!E13 | F13: ='CO–PO Attainment Summary'!F13 | G13: ='CO–PO Attainment Summary'!G13 | H13: ='CO–PO Attainment Summary'!H13 | I13: =IFERROR(AVERAGEIFS('Continuous Assessment Records'!L:L,'Continuous Assessment Records'!A:A,$A13,'Continuous Assessment Records'!F:F,$B13,'Continuous Assessment Records'!C:C,"Assignment"),"") | J13: =IFERROR(AVERAGEIFS('Continuous Assessment Records'!L:L,'Continuous Assessment Records'!A:A,$A13,'Continuous Assessment Records'!F:F,$B13,'Continuous Assessment Records'!C:C,"Unit Test"),"") | K13: =IFERROR(AVERAGEIFS('Continuous Assessment Records'!L:L,'Continuous Assessment Records'!A:A,$A13,'Continuous Assessment Records'!F:F,$B13,'Continuous Assessment Records'!C:C,"Mid-Term"),"") | L13: =IF(OR(I13="",J13="",K13=""),"",I13*$I$205+J13*$J$205+K13*$K$205) | M13: =IF(L13="","",IF(L13>=0.7,3,IF(L13>=0.6,2,IF(L13>=0.5,1,0)))) | N13: ='CO–PO Attainment Summary'!E13 | O13: =IF(M13="",'CO–PO Attainment Summary'!F13,ROUND(0.8*M13+0.2*N13,0))
... A201: ='CO–PO Attainment Summary'!A201 | B201: ='CO–PO Attainment Summary'!B201 | C201: ='CO–PO Attainment Summary'!C201 | D201: ='CO–PO Attainment Summary'!D201 | E201: ='CO–PO Attainment Summary'!E201 | F201: ='CO–PO Attainment Summary'!F201 | G201: ='CO–PO Attainment Summary'!G201 | H201: ='CO–PO Attainment Summary'!H201 | I201: =IFERROR(AVERAGEIFS('Continuous Assessment Records'!L:L,'Continuous Assessment Records'!A:A,$A201,'Continuous Assessment Records'!F:F,$B201,'Continuous Assessment Records'!C:C,"Assignment"),"") | J201: =IFERROR(AVERAGEIFS('Continuous Assessment Records'!L:L,'Continuous Assessment Records'!A:A,$A201,'Continuous Assessment Records'!F:F,$B201,'Continuous Assessment Records'!C:C,"Unit Test"),"") | K201: =IFERROR(AVERAGEIFS('Continuous Assessment Records'!L:L,'Continuous Assessment Records'!A:A,$A201,'Continuous Assessment Records'!F:F,$B201,'Continuous Assessment Records'!C:C,"Mid-Term"),"") | L201: =IF(OR(I201="",J201="",K201=""),"",I201*$I$205+J201*$J$205+K201*$K$205) | M201: =IF(L201="","",IF(L201>=0.7,3,IF(L201>=0.6,2,IF(L201>=0.5,1,0)))) | N201: ='CO–PO Attainment Summary'!E201 | O201: =IF(M201="",'CO–PO Attainment Summary'!F201,ROUND(0.8*M201+0.2*N201,0))
A203: Weights (Edit as needed; must sum to 1.0)
I204: Assignment Weight | J204: Unit Test Weight | K204: Mid-Term Weight
I205: 0.2 | J205: 0.3 | K205: 0.5
A207: Average Final Attainment | B207: =IFERROR(AVERAGE(O2:O200),"")
A209: Count of COs at Level 3 | B209: =COUNTIF(O2:O200,3)
A210: Count of COs at Level 2 | B210: =COUNTIF(O2:O200,2)
A211: Count of COs at Level 1 | B211: =COUNTIF(O2:O200,1)
A212: Count of COs at Level 0 | B212: =COUNTIF(O2:O200,0)

Sheet Assignment-wise Attainment
A1: CO | B1: Assignments Mapped | C1: Avg % (Auto) | D1: Attainment Level (0–3 Auto) | E1: PO(s) Mapped | F1: PSO(s) Mapped
A3: CO1 | B3: =TEXTJOIN(", ",TRUE,IF('Assignment Mapping'!F$2:F$1000=A3,'Assignment Mapping'!C$2:C$1000,"")) | C3: =IFERROR(AVERAGEIFS('Continuous Assessment Records'!L:L,'Continuous Assessment Records'!F:F,A3,'Continuous Assessment Records'!C:C,"Assignment"),"") | D3: =IF(C3="","",IF(C3>=0.7,3,IF(C3>=0.6,2,IF(C3>=0.5,1,0)))) | E3: =TEXTJOIN(", ",TRUE,IF('Assignment Mapping'!F$2:F$1000=A3,'Assignment Mapping'!G$2:G$1000,"")) | F3: =TEXTJOIN(", ",TRUE,IF('Assignment Mapping'!F$2:F$1000=A3,'Assignment Mapping'!H$2:H$1000,""))
A4: CO2 | B4: =TEXTJOIN(", ",TRUE,IF('Assignment Mapping'!F$2:F$1000=A4,'Assignment Mapping'!C$2:C$1000,"")) | C4: =IFERROR(AVERAGEIFS('Continuous Assessment Records'!L:L,'Continuous Assessment Records'!F:F,A4,'Continuous Assessment Records'!C:C,"Assignment"),"") | D4: =IF(C4="","",IF(C4>=0.7,3,IF(C4>=0.6,2,IF(C4>=0.5,1,0)))) | E4: =TEXTJOIN(", ",TRUE,IF('Assignment Mapping'!F$2:F$1000=A4,'Assignment Mapping'!G$2:G$1000,"")) | F4: =TEXTJOIN(", ",TRUE,IF('Assignment Mapping'!F$2:F$1000=A4,'Assignment Mapping'!H$2:H$1000,""))
A5: CO3 | B5: =TEXTJOIN(", ",TRUE,IF('Assignment Mapping'!F$2:F$1000=A5,'Assignment Mapping'!C$2:C$1000,"")) | C5: =IFERROR(AVERAGEIFS('Continuous Assessment Records'!L:L,'Continuous Assessment Records'!F:F,A5,'Continuous Assessment Records'!C:C,"Assignment"),"") | D5: =IF(C5="","",IF(C5>=0.7,3,IF(C5>=0.6,2,IF(C5>=0.5,1,0)))) | E5: =TEXTJOIN(", ",TRUE,IF('Assignment Mapping'!F$2:F$1000=A5,'Assignment Mapping'!G$2:G$1000,"")) | F5: =TEXTJOIN(", ",TRUE,IF('Assignment Mapping'!F$2:F$1000=A5,'Assignment Mapping'!H$2:H$1000,""))
A6: CO4 | B6: =TEXTJOIN(", ",TRUE,IF('Assignment Mapping'!F$2:F$1000=A6,'Assignment Mapping'!C$2:C$1000,"")) | C6: =IFERROR(AVERAGEIFS('Continuous Assessment Records'!L:L,'Continuous Assessment Records'!F:F,A6,'Continuous Assessment Records'!C:C,"Assignment"),"") | D6: =IF(C6="","",IF(C6>=0.7,3,IF(C6>=0.6,2,IF(C6>=0.5,1,0)))) | E6: =TEXTJOIN(", ",TRUE,IF('Assignment Mapping'!F$2:F$1000=A6,'Assignment Mapping'!G$2:G$1000,"")) | F6: =TEXTJOIN(", ",TRUE,IF('Assignment Mapping'!F$2:F$1000=A6,'Assignment Mapping'!H$2:H$1000,""))

Sheet Unit Test-wise Attainment
A1: CO | B1: Unit Test Questions Mapped | C1: Avg % (Auto) | D1: Attainment Level (0–3 Auto) | E1: PO(s) Mapped | F1: PSO(s) Mapped
A3: CO1 | B3: =TEXTJOIN(", ",TRUE,IF('Unit Test Mapping'!G$2:G$1000=A3,'Unit Test Mapping'!D$2:D$1000,"")) | C3: =IFERROR(AVERAGEIFS('Continuous Assessment Records'!L:L,'Continuous Assessment Records'!F:F,A3,'Continuous Assessment Records'!C:C,"Unit Test"),"") | D3: =IF(C3="","",IF(C3>=0.7,3,IF(C3>=0.6,2,IF(C3>=0.5,1,0)))) | E3: =TEXTJOIN(", ",TRUE,IF('Unit Test Mapping'!G$2:G$1000=A3,'Unit Test Mapping'!H$2:H$1000,"")) | F3: =TEXTJOIN(", ",TRUE,IF('Unit Test Mapping'!G$2:G$1000=A3,'Unit Test Mapping'!I$2:I$1000,""))
A4: CO2 | B4: =TEXTJOIN(", ",TRUE,IF('Unit Test Mapping'!G$2:G$1000=A4,'Unit Test Mapping'!D$2:D$1000,"")) | C4: =IFERROR(AVERAGEIFS('Continuous Assessment Records'!L:L,'Continuous Assessment Records'!F:F,A4,'Continuous Assessment Records'!C:C,"Unit Test"),"") | D4: =IF(C4="","",IF(C4>=0.7,3,IF(C4>=0.6,2,IF(C4>=0.5,1,0)))) | E4: =TEXTJOIN(", ",TRUE,IF('Unit Test Mapping'!G$2:G$1000=A4,'Unit Test Mapping'!H$2:H$1000,"")) | F4: =TEXTJOIN(", ",TRUE,IF('Unit Test Mapping'!G$2:G$1000=A4,'Unit Test Mapping'!I$2:I$1000,""))
A5: CO3 | B5: =TEXTJOIN(", ",TRUE,IF('Unit Test Mapping'!G$2:G$1000=A5,'Unit Test Mapping'!D$2:D$1000,"")) | C5: =IFERROR(AVERAGEIFS('Continuous Assessment Records'!L:L,'Continuous Assessment Records'!F:F,A5,'Continuous Assessment Records'!C:C,"Unit Test"),"") | D5: =IF(C5="","",IF(C5>=0.7,3,IF(C5>=0.6,2,IF(C5>=0.5,1,0)))) | E5: =TEXTJOIN(", ",TRUE,IF('Unit Test Mapping'!G$2:G$1000=A5,'Unit Test Mapping'!H$2:H$1000,"")) | F5: =TEXTJOIN(", ",TRUE,IF('Unit Test Mapping'!G$2:G$1000=A5,'Unit Test Mapping'!I$2:I$1000,""))
A6: CO4 | B6: =TEXTJOIN(", ",TRUE,IF('Unit Test Mapping'!G$2:G$1000=A6,'Unit Test Mapping'!D$2:D$1000,"")) | C6: =IFERROR(AVERAGEIFS('Continuous Assessment Records'!L:L,'Continuous Assessment Records'!F:F,A6,'Continuous Assessment Records'!C:C,"Unit Test"),"") | D6: =IF(C6="","",IF(C6>=0.7,3,IF(C6>=0.6,2,IF(C6>=0.5,1,0)))) | E6: =TEXTJOIN(", ",TRUE,IF('Unit Test Mapping'!G$2:G$1000=A6,'Unit Test Mapping'!H$2:H$1000,"")) | F6: =TEXTJOIN(", ",TRUE,IF('Unit Test Mapping'!G$2:G$1000=A6,'Unit Test Mapping'!I$2:I$1000,""))

Sheet Mid-Term-wise Attainment
A1: CO | B1: Mid-Term Questions Mapped | C1: Avg % (Auto) | D1: Attainment Level (0–3 Auto) | E1: PO(s) Mapped | F1: PSO(s) Mapped
A3: CO1 | B3: =TEXTJOIN(", ",TRUE,IF('Mid-Term Mapping'!G$2:G$1000=A3,'Mid-Term Mapping'!D$2:D$1000,"")) | C3: =IFERROR(AVERAGEIFS('Continuous Assessment Records'!L:L,'Continuous Assessment Records'!F:F,A3,'Continuous Assessment Records'!C:C,"Mid-Term"),"") | D3: =IF(C3="","",IF(C3>=0.7,3,IF(C3>=0.6,2,IF(C3>=0.5,1,0)))) | E3: =TEXTJOIN(", ",TRUE,IF('Mid-Term Mapping'!G$2:G$1000=A3,'Mid-Term Mapping'!H$2:H$1000,"")) | F3: =TEXTJOIN(", ",TRUE,IF('Mid-Term Mapping'!G$2:G$1000=A3,'Mid-Term Mapping'!I$2:I$1000,""))
A4: CO2 | B4: =TEXTJOIN(", ",TRUE,IF('Mid-Term Mapping'!G$2:G$1000=A4,'Mid-Term Mapping'!D$2:D$1000,"")) | C4: =IFERROR(AVERAGEIFS('Continuous Assessment Records'!L:L,'Continuous Assessment Records'!F:F,A4,'Continuous Assessment Records'!C:C,"Mid-Term"),"") | D4: =IF(C4="","",IF(C4>=0.7,3,IF(C4>=0.6,2,IF(C4>=0.5,1,0)))) | E4: =TEXTJOIN(", ",TRUE,IF('Mid-Term Mapping'!G$2:G$1000=A4,'Mid-Term Mapping'!H$2:H$1000,"")) | F4: =TEXTJOIN(", ",TRUE,IF('Mid-Term Mapping'!G$2:G$1000=A4,'Mid-Term Mapping'!I$2:I$1000,""))
A5: CO3 | B5: =TEXTJOIN(", ",TRUE,IF('Mid-Term Mapping'!G$2:G$1000=A5,'Mid-Term Mapping'!D$2:D$1000,"")) | C5: =IFERROR(AVERAGEIFS('Continuous Assessment Records'!L:L,'Continuous Assessment Records'!F:F,A5,'Continuous Assessment Records'!C:C,"Mid-Term"),"") | D5: =IF(C5="","",IF(C5>=0.7,3,IF(C5>=0.6,2,IF(C5>=0.5,1,0)))) | E5: =TEXTJOIN(", ",TRUE,IF('Mid-Term Mapping'!G$2:G$1000=A5,'Mid-Term Mapping'!H$2:H$1000,"")) | F5: =TEXTJOIN(", ",TRUE,IF('Mid-Term Mapping'!G$2:G$1000=A5,'Mid-Term Mapping'!I$2:I$1000,""))
A6: CO4 | B6: =TEXTJOIN(", ",TRUE,IF('Mid-Term Mapping'!G$2:G$1000=A6,'Mid-Term Mapping'!D$2:D$1000,"")) | C6: =IFERROR(AVERAGEIFS('Continuous Assessment Records'!L:L,'Continuous Assessment Records'!F:F,A6,'Continuous Assessment Records'!C:C,"Mid-Term"),"") | D6: =IF(C6="","",IF(C6>=0.7,3,IF(C6>=0.6,2,IF(C6>=0.5,1,0)))) | E6: =TEXTJOIN(", ",TRUE,IF('Mid-Term Mapping'!G$2:G$1000=A6,'Mid-Term Mapping'!H$2:H$1000,"")) | F6: =TEXTJOIN(", ",TRUE,IF('Mid-Term Mapping'!G$2:G$1000=A6,'Mid-Term Mapping'!I$2:I$1000,""))

Sheet CO Attainment Summary
A1: Consolidated CO Attainment Summary (Assignments + UTs + Mid-Terms + Indirect)
A2: CO | B2: Assignment Avg % (Auto) | C2: UT Avg % (Auto) | D2: Mid-Term Avg % (Auto) | E2: Weighted Avg % (Auto) | F2: Direct Attainment Level (Auto) | G2: Indirect Attainment (Manual Entry) | H2: Final Attainment Level (Auto) | I2: PO(s) Mapped | J2: PSO(s) Mapped
A3: CO1 | B3: ='Assignment-wise Attainment'!C3 | C3: ='Unit Test-wise Attainment'!C3 | D3: ='Mid-Term-wise Attainment'!C3 | E3: =IF(B3="","",B3*$B$20+C3*$C$20+D3*$D$20) | F3: =IF(E3="","",IF(E3>=0.7,3,IF(E3>=0.6,2,IF(E3>=0.5,1,0)))) | H3: =IF(OR(F3="",G3=""),F3,ROUND(0.8*F3+0.2*G3,0)) | I3: =TEXTJOIN(", ",TRUE,UNIQUE(FILTER('Assignment Mapping'!G$2:G$1000,'Assignment Mapping'!F$2:F$1000=A3))) | J3: =TEXTJOIN(", ",TRUE,UNIQUE(FILTER('Assignment Mapping'!H$2:H$1000,'Assignment Mapping'!F$2:F$1000=A3)))
A4: CO2 | B4: ='Assignment-wise Attainment'!C4 | C4: ='Unit Test-wise Attainment'!C4 | D4: ='Mid-Term-wise Attainment'!C4 | E4: =IF(B4="","",B4*$B$20+C4*$C$20+D4*$D$20) | F4: =IF(E4="","",IF(E4>=0.7,3,IF(E4>=0.6,2,IF(E4>=0.5,1,0)))) | H4: =IF(OR(F4="",G4=""),F4,ROUND(0.8*F4+0.2*G4,0)) | I4: =TEXTJOIN(", ",TRUE,UNIQUE(FILTER('Assignment Mapping'!G$2:G$1000,'Assignment Mapping'!F$2:F$1000=A4))) | J4: =TEXTJOIN(", ",TRUE,UNIQUE(FILTER('Assignment Mapping'!H$2:H$1000,'Assignment Mapping'!F$2:F$1000=A4)))
A5: CO3 | B5: ='Assignment-wise Attainment'!C5 | C5: ='Unit Test-wise Attainment'!C5 | D5: ='Mid-Term-wise Attainment'!C5 | E5: =IF(B5="","",B5*$B$20+C5*$C$20+D5*$D$20) | F5: =IF(E5="","",IF(E5>=0.7,3,IF(E5>=0.6,2,IF(E5>=0.5,1,0)))) | H5: =IF(OR(F5="",G5=""),F5,ROUND(0.8*F5+0.2*G5,0)) | I5: =TEXTJOIN(", ",TRUE,UNIQUE(FILTER('Assignment Mapping'!G$2:G$1000,'Assignment Mapping'!F$2:F$1000=A5))) | J5: =TEXTJOIN(", ",TRUE,UNIQUE(FILTER('Assignment Mapping'!H$2:H$1000,'Assignment Mapping'!F$2:F$1000=A5)))
A6: CO4 | B6: ='Assignment-wise Attainment'!C6 | C6: ='Unit Test-wise Attainment'!C6 | D6: ='Mid-Term-wise Attainment'!C6 | E6: =IF(B6="","",B6*$B$20+C6*$C$20+D6*$D$20) | F6: =IF(E6="","",IF(E6>=0.7,3,IF(E6>=0.6,2,IF(E6>=0.5,1,0)))) | H6: =IF(OR(F6="",G6=""),F6,ROUND(0.8*F6+0.2*G6,0)) | I6: =TEXTJOIN(", ",TRUE,UNIQUE(FILTER('Assignment Mapping'!G$2:G$1000,'Assignment Mapping'!F$2:F$1000=A6))) | J6: =TEXTJOIN(", ",TRUE,UNIQUE(FILTER('Assignment Mapping'!H$2:H$1000,'Assignment Mapping'!F$2:F$1000=A6)))
A19: Weights (Editable; sum=1.0)
B20: 0.2 | C20: 0.3 | D20: 0.5

Sheet CO–PO & PSO Matrix
A1: CO–PO & CO–PSO Mapping Matrix (Strength Values: 3=Strong, 2=Moderate, 1=Slight, Blank=None)
A2: CO | B2: PO1 | C2: PO2 | D2: PO3 | E2: PO4 | F2: PO5 | G2: PO6 | H2: PO7 | I2: PO8 | J2: PO9 | K2: PO10 | L2: PO11 | M2: PO12 | N2: PSO1 | O2: PSO2 | P2: PSO3
A3: CO1
A4: CO2
A5: CO3
A6: CO4
A8: Note: Fill strength values (3/2/1) per CO vs PO/PSO. Used by PO_PSO Aggregation.

Sheet PO_PSO Aggregation
A1: PO and PSO Aggregation (Weighted Average of CO Final Attainments × Mapping Strengths)
A3: PO | B3: Contributing COs | C3: Aggregated Attainment (0–3 Auto)
A4: PO1 | B4: =TEXTJOIN(", ",TRUE,IF('CO–PO & PSO Matrix'!B$3:B$6<>"",'CO–PO & PSO Matrix'!$A$3:$A$6,"")) | C4: =IF(SUM('CO–PO & PSO Matrix'!B$3:B$6)=0,"",SUMPRODUCT(INDEX('CO Attainment Summary'!$H$3:$H$6, MATCH('CO–PO & PSO Matrix'!$A$3:$A$6, 'CO Attainment Summary'!$A$3:$A$6,0)),'CO–PO & PSO Matrix'!B$3:B$6)/SUM('CO–PO & PSO Matrix'!B$3:B$6))
A5: PO2 | B5: =TEXTJOIN(", ",TRUE,IF('CO–PO & PSO Matrix'!C$3:C$6<>"",'CO–PO & PSO Matrix'!$A$3:$A$6,"")) | C5: =IF(SUM('CO–PO & PSO Matrix'!C$3:C$6)=0,"",SUMPRODUCT(INDEX('CO Attainment Summary'!$H$3:$H$6, MATCH('CO–PO & PSO Matrix'!$A$3:$A$6, 'CO Attainment Summary'!$A$3:$A$6,0)),'CO–PO & PSO Matrix'!C$3:C$6)/SUM('CO–PO & PSO Matrix'!C$3:C$6))
A6: PO3 | B6: =TEXTJOIN(", ",TRUE,IF('CO–PO & PSO Matrix'!D$3:D$6<>"",'CO–PO & PSO Matrix'!$A$3:$A$6,"")) | C6: =IF(SUM('CO–PO & PSO Matrix'!D$3:D$6)=0,"",SUMPRODUCT(INDEX('CO Attainment Summary'!$H$3:$H$6, MATCH('CO–PO & PSO Matrix'!$A$3:$A$6, 'CO Attainment Summary'!$A$3:$A$6,0)),'CO–PO & PSO Matrix'!D$3:D$6)/SUM('CO–PO & PSO Matrix'!D$3:D$6))
A7: PO4 | B7: =TEXTJOIN(", ",TRUE,IF('CO–PO & PSO Matrix'!E$3:E$6<>"",'CO–PO & PSO Matrix'!$A$3:$A$6,"")) | C7: =IF(SUM('CO–PO & PSO Matrix'!E$3:E$6)=0,"",SUMPRODUCT(INDEX('CO Attainment Summary'!$H$3:$H$6, MATCH('CO–PO & PSO Matrix'!$A$3:$A$6, 'CO Attainment Summary'!$A$3:$A$6,0)),'CO–PO & PSO Matrix'!E$3:E$6)/SUM('CO–PO & PSO Matrix'!E$3:E$6))
A8: PO5 | B8: =TEXTJOIN(", ",TRUE,IF('CO–PO & PSO Matrix'!F$3:F$6<>"",'CO–PO & PSO Matrix'!$A$3:$A$6,"")) | C8: =IF(SUM('CO–PO & PSO Matrix'!F$3:F$6)=0,"",SUMPRODUCT(INDEX('CO Attainment Summary'!$H$3:$H$6, MATCH('CO–PO & PSO Matrix'!$A$3:$A$6, 'CO Attainment Summary'!$A$3:$A$6,0)),'CO–PO & PSO Matrix'!F$3:F$6)/SUM('CO–PO & PSO Matrix'!F$3:F$6))
A9: PO6 | B9: =TEXTJOIN(", ",TRUE,IF('CO–PO & PSO Matrix'!G$3:G$6<>"",'CO–PO & PSO Matrix'!$A$3:$A$6,"")) | C9: =IF(SUM('CO–PO & PSO Matrix'!G$3:G$6)=0,"",SUMPRODUCT(INDEX('CO Attainment Summary'!$H$3:$H$6, MATCH('CO–PO & PSO Matrix'!$A$3:$A$6, 'CO Attainment Summary'!$A$3:$A$6,0)),'CO–PO & PSO Matrix'!G$3:G$6)/SUM('CO–PO & PSO Matrix'!G$3:G$6))
A10: PO7 | B10: =TEXTJOIN(", ",TRUE,IF('CO–PO & PSO Matrix'!H$3:H$6<>"",'CO–PO & PSO Matrix'!$A$3:$A$6,"")) | C10: =IF(SUM('CO–PO & PSO Matrix'!H$3:H$6)=0,"",SUMPRODUCT(INDEX('CO Attainment Summary'!$H$3:$H$6, MATCH('CO–PO & PSO Matrix'!$A$3:$A$6, 'CO Attainment Summary'!$A$3:$A$6,0)),'CO–PO & PSO Matrix'!H$3:H$6)/SUM('CO–PO & PSO Matrix'!H$3:H$6))
A11: PO8 | B11: =TEXTJOIN(", ",TRUE,IF('CO–PO & PSO Matrix'!I$3:I$6<>"",'CO–PO & PSO Matrix'!$A$3:$A$6,"")) | C11: =IF(SUM('CO–PO & PSO Matrix'!I$3:I$6)=0,"",SUMPRODUCT(INDEX('CO Attainment Summary'!$H$3:$H$6, MATCH('CO–PO & PSO Matrix'!$A$3:$A$6, 'CO Attainment Summary'!$A$3:$A$6,0)),'CO–PO & PSO Matrix'!I$3:I$6)/SUM('CO–PO & PSO Matrix'!I$3:I$6))
A12: PO9 | B12: =TEXTJOIN(", ",TRUE,IF('CO–PO & PSO Matrix'!J$3:J$6<>"",'CO–PO & PSO Matrix'!$A$3:$A$6,"")) | C12: =IF(SUM('CO–PO & PSO Matrix'!J$3:J$6)=0,"",SUMPRODUCT(INDEX('CO Attainment Summary'!$H$3:$H$6, MATCH('CO–PO & PSO Matrix'!$A$3:$A$6, 'CO Attainment Summary'!$A$3:$A$6,0)),'CO–PO & PSO Matrix'!J$3:J$6)/SUM('CO–PO & PSO Matrix'!J$3:J$6))
A13: PO10 | B13: =TEXTJOIN(", ",TRUE,IF('CO–PO & PSO Matrix'!K$3:K$6<>"",'CO–PO & PSO Matrix'!$A$3:$A$6,"")) | C13: =IF(SUM('CO–PO & PSO Matrix'!K$3:K$6)=0,"",SUMPRODUCT(INDEX('CO Attainment Summary'!$H$3:$H$6, MATCH('CO–PO & PSO Matrix'!$A$3:$A$6, 'CO Attainment Summary'!$A$3:$A$6,0)),'CO–PO & PSO Matrix'!K$3:K$6)/SUM('CO–PO & PSO Matrix'!K$3:K$6))
A14: PO11 | B14: =TEXTJOIN(", ",TRUE,IF('CO–PO & PSO Matrix'!L$3:L$6<>"",'CO–PO & PSO Matrix'!$A$3:$A$6,"")) | C14: =IF(SUM('CO–PO & PSO Matrix'!L$3:L$6)=0,"",SUMPRODUCT(INDEX('CO Attainment Summary'!$H$3:$H$6, MATCH('CO–PO & PSO Matrix'!$A$3:$A$6, 'CO Attainment Summary'!$A$3:$A$6,0)),'CO–PO & PSO Matrix'!L$3:L$6)/SUM('CO–PO & PSO Matrix'!L$3:L$6))
A15: PO12 | B15: =TEXTJOIN(", ",TRUE,IF('CO–PO & PSO Matrix'!M$3:M$6<>"",'CO–PO & PSO Matrix'!$A$3:$A$6,"")) | C15: =IF(SUM('CO–PO & PSO Matrix'!M$3:M$6)=0,"",SUMPRODUCT(INDEX('CO Attainment Summary'!$H$3:$H$6, MATCH('CO–PO & PSO Matrix'!$A$3:$A$6, 'CO Attainment Summary'!$A$3:$A$6,0)),'CO–PO & PSO Matrix'!M$3:M$6)/SUM('CO–PO & PSO Matrix'!M$3:M$6))
A22: PSO | B22: Contributing COs | C22: Aggregated Attainment (0–3 Auto)
A23: PSO1 | B23: =TEXTJOIN(", ",TRUE,IF('CO–PO & PSO Matrix'!N$3:N$6<>"",'CO–PO & PSO Matrix'!$A$3:$A$6,"")) | C23: =IF(SUM('CO–PO & PSO Matrix'!N$3:N$6)=0,"",SUMPRODUCT(INDEX('CO Attainment Summary'!$H$3:$H$6, MATCH('CO–PO & PSO Matrix'!$A$3:$A$6, 'CO Attainment Summary'!$A$3:$A$6,0)),'CO–PO & PSO Matrix'!N$3:N$6)/SUM('CO–PO & PSO Matrix'!N$3:N$6))
A24: PSO2 | B24: =TEXTJOIN(", ",TRUE,IF('CO–PO & PSO Matrix'!O$3:O$6<>"",'CO–PO & PSO Matrix'!$A$3:$A$6,"")) | C24: =IF(SUM('CO–PO & PSO Matrix'!O$3:O$6)=0,"",SUMPRODUCT(INDEX('CO Attainment Summary'!$H$3:$H$6, MATCH('CO–PO & PSO Matrix'!$A$3:$A$6, 'CO Attainment Summary'!$A$3:$A$6,0)),'CO–PO & PSO Matrix'!O$3:O$6)/SUM('CO–PO & PSO Matrix'!O$3:O$6))
A25: PSO3 | B25: =TEXTJOIN(", ",TRUE,IF('CO–PO & PSO Matrix'!P$3:P$6<>"",'CO–PO & PSO Matrix'!$A$3:$A$6,"")) | C25: =IF(SUM('CO–PO & PSO Matrix'!P$3:P$6)=0,"",SUMPRODUCT(INDEX('CO Attainment Summary'!$H$3:$H$6, MATCH('CO–PO & PSO Matrix'!$A$3:$A$6, 'CO Attainment Summary'!$A$3:$A$6,0)),'CO–PO & PSO Matrix'!P$3:P$6)/SUM('CO–PO & PSO Matrix'!P$3:P$6))
A35: Final Aggregated PO/PSO Attainment Table (Expanded with CO Finals & Mapping Strengths)
A36: PO/PSO | B36: Contributing COs | C36: CO Final Attainments | D36: Mapping Strengths | E36: Aggregated Attainment (0–3)
A37: PO1 | B37: =TEXTJOIN(", ",TRUE,IF('CO–PO & PSO Matrix'!B$3:B$6<>"",'CO–PO & PSO Matrix'!$A$3:$A$6,"")) | C37: =TEXTJOIN(", ",TRUE,IF('CO–PO & PSO Matrix'!B$3:B$6<>"", INDEX('CO Attainment Summary'!$H$3:$H$6, MATCH('CO–PO & PSO Matrix'!$A$3:$A$6, 'CO Attainment Summary'!$A$3:$A$6,0)), "")) | D37: =TEXTJOIN(", ",TRUE,IF('CO–PO & PSO Matrix'!B$3:B$6<>"", 'CO–PO & PSO Matrix'!B$3:B$6, "")) | E37: =IF(SUM('CO–PO & PSO Matrix'!B$3:B$6)=0,"",SUMPRODUCT(INDEX('CO Attainment Summary'!$H$3:$H$6, MATCH('CO–PO & PSO Matrix'!$A$3:$A$6, 'CO Attainment Summary'!$A$3:$A$6,0)),'CO–PO & PSO Matrix'!B$3:B$6)/SUM('CO–PO & PSO Matrix'!B$3:B$6))
A38: PO2 | B38: =TEXTJOIN(", ",TRUE,IF('CO–PO & PSO Matrix'!C$3:C$6<>"",'CO–PO & PSO Matrix'!$A$3:$A$6,"")) | C38: =TEXTJOIN(", ",TRUE,IF('CO–PO & PSO Matrix'!C$3:C$6<>"", INDEX('CO Attainment Summary'!$H$3:$H$6, MATCH('CO–PO & PSO Matrix'!$A$3:$A$6, 'CO Attainment Summary'!$A$3:$A$6,0)), "")) | D38: =TEXTJOIN(", ",TRUE,IF('CO–PO & PSO Matrix'!C$3:C$6<>"", 'CO–PO & PSO Matrix'!C$3:C$6, "")) | E38: =IF(SUM('CO–PO & PSO Matrix'!C$3:C$6)=0,"",SUMPRODUCT(INDEX('CO Attainment Summary'!$H$3:$H$6, MATCH('CO–PO & PSO Matrix'!$A$3:$A$6, 'CO Attainment Summary'!$A$3:$A$6,0)),'CO–PO & PSO Matrix'!C$3:C$6)/SUM('CO–PO & PSO Matrix'!C$3:C$6))
A39: PO3 | B39: =TEXTJOIN(", ",TRUE,IF('CO–PO & PSO Matrix'!D$3:D$6<>"",'CO–PO & PSO Matrix'!$A$3:$A$6,"")) | C39: =TEXTJOIN(", ",TRUE,IF('CO–PO & PSO Matrix'!D$3:D$6<>"", INDEX('CO Attainment Summary'!$H$3:$H$6, MATCH('CO–PO & PSO Matrix'!$A$3:$A$6, 'CO Attainment Summary'!$A$3:$A$6,0)), "")) | D39: =TEXTJOIN(", ",TRUE,IF('CO–PO & PSO Matrix'!D$3:D$6<>"", 'CO–PO & PSO Matrix'!D$3:D$6, "")) | E39: =IF(SUM('CO–PO & PSO Matrix'!D$3:D$6)=0,"",SUMPRODUCT(INDEX('CO Attainment Summary'!$H$3:$H$6, MATCH('CO–PO & PSO Matrix'!$A$3:$A$6, 'CO Attainment Summary'!$A$3:$A$6,0)),'CO–PO & PSO Matrix'!D$3:D$6)/SUM('CO–PO & PSO Matrix'!D$3:D$6))
A40: PO4 | B40: =TEXTJOIN(", ",TRUE,IF('CO–PO & PSO Matrix'!E$3:E$6<>"",'CO–PO & PSO Matrix'!$A$3:$A$6,"")) | C40: =TEXTJOIN(", ",TRUE,IF('CO–PO & PSO Matrix'!E$3:E$6<>"", INDEX('CO Attainment Summary'!$H$3:$H$6, MATCH('CO–PO & PSO Matrix'!$A$3:$A$6, 'CO Attainment Summary'!$A$3:$A$6,0)), "")) | D40: =TEXTJOIN(", ",TRUE,IF('CO–PO & PSO Matrix'!E$3:E$6<>"", 'CO–PO & PSO Matrix'!E$3:E$6, "")) | E40: =IF(SUM('CO–PO & PSO Matrix'!E$3:E$6)=0,"",SUMPRODUCT(INDEX('CO Attainment Summary'!$H$3:$H$6, MATCH('CO–PO & PSO Matrix'!$A$3:$A$6, 'CO Attainment Summary'!$A$3:$A$6,0)),'CO–PO & PSO Matrix'!E$3:E$6)/SUM('CO–PO & PSO Matrix'!E$3:E$6))
A41: PO5 | B41: =TEXTJOIN(", ",TRUE,IF('CO–PO & PSO Matrix'!F$3:F$6<>"",'CO–PO & PSO Matrix'!$A$3:$A$6,"")) | C41: =TEXTJOIN(", ",TRUE,IF('CO–PO & PSO Matrix'!F$3:F$6<>"", INDEX('CO Attainment Summary'!$H$3:$H$6, MATCH('CO–PO & PSO Matrix'!$A$3:$A$6, 'CO Attainment Summary'!$A$3:$A$6,0)), "")) | D41: =TEXTJOIN(", ",TRUE,IF('CO–PO & PSO Matrix'!F$3:F$6<>"", 'CO–PO & PSO Matrix'!F$3:F$6, "")) | E41: =IF(SUM('CO–PO & PSO Matrix'!F$3:F$6)=0,"",SUMPRODUCT(INDEX('CO Attainment Summary'!$H$3:$H$6, MATCH('CO–PO & PSO Matrix'!$A$3:$A$6, 'CO Attainment Summary'!$A$3:$A$6,0)),'CO–PO & PSO Matrix'!F$3:F$6)/SUM('CO–PO & PSO Matrix'!F$3:F$6))
A42: PO6 | B42: =TEXTJOIN(", ",TRUE,IF('CO–PO & PSO Matrix'!G$3:G$6<>"",'CO–PO & PSO Matrix'!$A$3:$A$6,"")) | C42: =TEXTJOIN(", ",TRUE,IF('CO–PO & PSO Matrix'!G$3:G$6<>"", INDEX('CO Attainment Summary'!$H$3:$H$6, MATCH('CO–PO & PSO Matrix'!$A$3:$A$6, 'CO Attainment Summary'!$A$3:$A$6,0)), "")) | D42: =TEXTJOIN(", ",TRUE,IF('CO–PO & PSO Matrix'!G$3:G$6<>"", 'CO–PO & PSO Matrix'!G$3:G$6, "")) | E42: =IF(SUM('CO–PO & PSO Matrix'!G$3:G$6)=0,"",SUMPRODUCT(INDEX('CO Attainment Summary'!$H$3:$H$6, MATCH('CO–PO & PSO Matrix'!$A$3:$A$6, 'CO Attainment Summary'!$A$3:$A$6,0)),'CO–PO & PSO Matrix'!G$3:G$6)/SUM('CO–PO & PSO Matrix'!G$3:G$6))
A43: PO7 | B43: =TEXTJOIN(", ",TRUE,IF('CO–PO & PSO Matrix'!H$3:H$6<>"",'CO–PO & PSO Matrix'!$A$3:$A$6,"")) | C43: =TEXTJOIN(", ",TRUE,IF('CO–PO & PSO Matrix'!H$3:H$6<>"", INDEX('CO Attainment Summary'!$H$3:$H$6, MATCH('CO–PO & PSO Matrix'!$A$3:$A$6, 'CO Attainment Summary'!$A$3:$A$6,0)), "")) | D43: =TEXTJOIN(", ",TRUE,IF('CO–PO & PSO Matrix'!H$3:H$6<>"", 'CO–PO & PSO Matrix'!H$3:H$6, "")) | E43: =IF(SUM('CO–PO & PSO Matrix'!H$3:H$6)=0,"",SUMPRODUCT(INDEX('CO Attainment Summary'!$H$3:$H$6, MATCH('CO–PO & PSO Matrix'!$A$3:$A$6, 'CO Attainment Summary'!$A$3:$A$6,0)),'CO–PO & PSO Matrix'!H$3:H$6)/SUM('CO–PO & PSO Matrix'!H$3:H$6))
A44: PO8 | B44: =TEXTJOIN(", ",TRUE,IF('CO–PO & PSO Matrix'!I$3:I$6<>"",'CO–PO & PSO Matrix'!$A$3:$A$6,"")) | C44: =TEXTJOIN(", ",TRUE,IF('CO–PO & PSO Matrix'!I$3:I$6<>"", INDEX('CO Attainment Summary'!$H$3:$H$6, MATCH('CO–PO & PSO Matrix'!$A$3:$A$6, 'CO Attainment Summary'!$A$3:$A$6,0)), "")) | D44: =TEXTJOIN(", ",TRUE,IF('CO–PO & PSO Matrix'!I$3:I$6<>"", 'CO–PO & PSO Matrix'!I$3:I$6, "")) | E44: =IF(SUM('CO–PO & PSO Matrix'!I$3:I$6)=0,"",SUMPRODUCT(INDEX('CO Attainment Summary'!$H$3:$H$6, MATCH('CO–PO & PSO Matrix'!$A$3:$A$6, 'CO Attainment Summary'!$A$3:$A$6,0)),'CO–PO & PSO Matrix'!I$3:I$6)/SUM('CO–PO & PSO Matrix'!I$3:I$6))
A45: PO9 | B45: =TEXTJOIN(", ",TRUE,IF('CO–PO & PSO Matrix'!J$3:J$6<>"",'CO–PO & PSO Matrix'!$A$3:$A$6,"")) | C45: =TEXTJOIN(", ",TRUE,IF('CO–PO & PSO Matrix'!J$3:J$6<>"", INDEX('CO Attainment Summary'!$H$3:$H$6, MATCH('CO–PO & PSO Matrix'!$A$3:$A$6, 'CO Attainment Summary'!$A$3:$A$6,0)), "")) | D45: =TEXTJOIN(", ",TRUE,IF('CO–PO & PSO Matrix'!J$3:J$6<>"", 'CO–PO & PSO Matrix'!J$3:J$6, "")) | E45: =IF(SUM('CO–PO & PSO Matrix'!J$3:J$6)=0,"",SUMPRODUCT(INDEX('CO Attainment Summary'!$H$3:$H$6, MATCH('CO–PO & PSO Matrix'!$A$3:$A$6, 'CO Attainment Summary'!$A$3:$A$6,0)),'CO–PO & PSO Matrix'!J$3:J$6)/SUM('CO–PO & PSO Matrix'!J$3:J$6))
A46: PO10 | B46: =TEXTJOIN(", ",TRUE,IF('CO–PO & PSO Matrix'!K$3:K$6<>"",'CO–PO & PSO Matrix'!$A$3:$A$6,"")) | C46: =TEXTJOIN(", ",TRUE,IF('CO–PO & PSO Matrix'!K$3:K$6<>"", INDEX('CO Attainment Summary'!$H$3:$H$6, MATCH('CO–PO & PSO Matrix'!$A$3:$A$6, 'CO Attainment Summary'!$A$3:$A$6,0)), "")) | D46: =TEXTJOIN(", ",TRUE,IF('CO–PO & PSO Matrix'!K$3:K$6<>"", 'CO–PO & PSO Matrix'!K$3:K$6, "")) | E46: =IF(SUM('CO–PO & PSO Matrix'!K$3:K$6)=0,"",SUMPRODUCT(INDEX('CO Attainment Summary'!$H$3:$H$6, MATCH('CO–PO & PSO Matrix'!$A$3:$A$6, 'CO Attainment Summary'!$A$3:$A$6,0)),'CO–PO & PSO Matrix'!K$3:K$6)/SUM('CO–PO & PSO Matrix'!K$3:K$6))
A47: PO11 | B47: =TEXTJOIN(", ",TRUE,IF('CO–PO & PSO Matrix'!L$3:L$6<>"",'CO–PO & PSO Matrix'!$A$3:$A$6,"")) | C47: =TEXTJOIN(", ",TRUE,IF('CO–PO & PSO Matrix'!L$3:L$6<>"", INDEX('CO Attainment Summary'!$H$3:$H$6, MATCH('CO–PO & PSO Matrix'!$A$3:$A$6, 'CO Attainment Summary'!$A$3:$A$6,0)), "")) | D47: =TEXTJOIN(", ",TRUE,IF('CO–PO & PSO Matrix'!L$3:L$6<>"", 'CO–PO & PSO Matrix'!L$3:L$6, "")) | E47: =IF(SUM('CO–PO & PSO Matrix'!L$3:L$6)=0,"",SUMPRODUCT(INDEX('CO Attainment Summary'!$H$3:$H$6, MATCH('CO–PO & PSO Matrix'!$A$3:$A$6, 'CO Attainment Summary'!$A$3:$A$6,0)),'CO–PO & PSO Matrix'!L$3:L$6)/SUM('CO–PO & PSO Matrix'!L$3:L$6))
A48: PO12 | B48: =TEXTJOIN(", ",TRUE,IF('CO–PO & PSO Matrix'!M$3:M$6<>"",'CO–PO & PSO Matrix'!$A$3:$A$6,"")) | C48: =TEXTJOIN(", ",TRUE,IF('CO–PO & PSO Matrix'!M$3:M$6<>"", INDEX('CO Attainment Summary'!$H$3:$H$6, MATCH('CO–PO & PSO Matrix'!$A$3:$A$6, 'CO Attainment Summary'!$A$3:$A$6,0)), "")) | D48: =TEXTJOIN(", ",TRUE,IF('CO–PO & PSO Matrix'!M$3:M$6<>"", 'CO–PO & PSO Matrix'!M$3:M$6, "")) | E48: =IF(SUM('CO–PO & PSO Matrix'!M$3:M$6)=0,"",SUMPRODUCT(INDEX('CO Attainment Summary'!$H$3:$H$6, MATCH('CO–PO & PSO Matrix'!$A$3:$A$6, 'CO Attainment Summary'!$A$3:$A$6,0)),'CO–PO & PSO Matrix'!M$3:M$6)/SUM('CO–PO & PSO Matrix'!M$3:M$6))
A49: PSO1 | B49: =TEXTJOIN(", ",TRUE,IF('CO–PO & PSO Matrix'!N$3:N$6<>"",'CO–PO & PSO Matrix'!$A$3:$A$6,"")) | C49: =TEXTJOIN(", ",TRUE,IF('CO–PO & PSO Matrix'!N$3:N$6<>"", INDEX('CO Attainment Summary'!$H$3:$H$6, MATCH('CO–PO & PSO Matrix'!$A$3:$A$6, 'CO Attainment Summary'!$A$3:$A$6,0)), "")) | D49: =TEXTJOIN(", ",TRUE,IF('CO–PO & PSO Matrix'!N$3:N$6<>"", 'CO–PO & PSO Matrix'!N$3:N$6, "")) | E49: =IF(SUM('CO–PO & PSO Matrix'!N$3:N$6)=0,"",SUMPRODUCT(INDEX('CO Attainment Summary'!$H$3:$H$6, MATCH('CO–PO & PSO Matrix'!$A$3:$A$6, 'CO Attainment Summary'!$A$3:$A$6,0)),'CO–PO & PSO Matrix'!N$3:N$6)/SUM('CO–PO & PSO Matrix'!N$3:N$6))
A50: PSO2 | B50: =TEXTJOIN(", ",TRUE,IF('CO–PO & PSO Matrix'!O$3:O$6<>"",'CO–PO & PSO Matrix'!$A$3:$A$6,"")) | C50: =TEXTJOIN(", ",TRUE,IF('CO–PO & PSO Matrix'!O$3:O$6<>"", INDEX('CO Attainment Summary'!$H$3:$H$6, MATCH('CO–PO & PSO Matrix'!$A$3:$A$6, 'CO Attainment Summary'!$A$3:$A$6,0)), "")) | D50: =TEXTJOIN(", ",TRUE,IF('CO–PO & PSO Matrix'!O$3:O$6<>"", 'CO–PO & PSO Matrix'!O$3:O$6, "")) | E50: =IF(SUM('CO–PO & PSO Matrix'!O$3:O$6)=0,"",SUMPRODUCT(INDEX('CO Attainment Summary'!$H$3:$H$6, MATCH('CO–PO & PSO Matrix'!$A$3:$A$6, 'CO Attainment Summary'!$A$3:$A$6,0)),'CO–PO & PSO Matrix'!O$3:O$6)/SUM('CO–PO & PSO Matrix'!O$3:O$6))
A51: PSO3 | B51: =TEXTJOIN(", ",TRUE,IF('CO–PO & PSO Matrix'!P$3:P$6<>"",'CO–PO & PSO Matrix'!$A$3:$A$6,"")) | C51: =TEXTJOIN(", ",TRUE,IF('CO–PO & PSO Matrix'!P$3:P$6<>"", INDEX('CO Attainment Summary'!$H$3:$H$6, MATCH('CO–PO & PSO Matrix'!$A$3:$A$6, 'CO Attainment Summary'!$A$3:$A$6,0)), "")) | D51: =TEXTJOIN(", ",TRUE,IF('CO–PO & PSO Matrix'!P$3:P$6<>"", 'CO–PO & PSO Matrix'!P$3:P$6, "")) | E51: =IF(SUM('CO–PO & PSO Matrix'!P$3:P$6)=0,"",SUMPRODUCT(INDEX('CO Attainment Summary'!$H$3:$H$6, MATCH('CO–PO & PSO Matrix'!$A$3:$A$6, 'CO Attainment Summary'!$A$3:$A$6,0)),'CO–PO & PSO Matrix'!P$3:P$6)/SUM('CO–PO & PSO Matrix'!P$3:P$6))

Sheet Attainment Calc Sheets
A1: Section A: Student-wise Attainment per CO (Raw to Levels)
A2: Roll No. | B2: Student Name | C2: CO | D2: Max Marks | E2: Marks Obtained | F2: % Score (Auto) | G2: Attainment Level (0–3)
A3: 101 | B3: A. Kumar | C3: CO1 | D3: 10 | E3: 8 | F3: =IF(D3=0,"",E3/D3) | G3: =IF(F3="","",IF(F3>=0.7,3,IF(F3>=0.6,2,IF(F3>=0.5,1,0))))
A4: 102 | B4: B. Singh | C4: CO1 | D4: 10 | E4: 6 | F4: =IF(D4=0,"",E4/D4) | G4: =IF(F4="","",IF(F4>=0.7,3,IF(F4>=0.6,2,IF(F4>=0.5,1,0))))
A5: 103 | B5: C. Rao | C5: CO1 | D5: 10 | E5: 5 | F5: =IF(D5=0,"",E5/D5) | G5: =IF(F5="","",IF(F5>=0.7,3,IF(F5>=0.6,2,IF(F5>=0.5,1,0))))
F6: =IF(D6=0,"",E6/D6) | G6: =IF(F6="","",IF(F6>=0.7,3,IF(F6>=0.6,2,IF(F6>=0.5,1,0))))
F7: =IF(D7=0,"",E7/D7) | G7: =IF(F7="","",IF(F7>=0.7,3,IF(F7>=0.6,2,IF(F7>=0.5,1,0))))
F8: =IF(D8=0,"",E8/D8) | G8: =IF(F8="","",IF(F8>=0.7,3,IF(F8>=0.6,2,IF(F8>=0.5,1,0))))
F9: =IF(D9=0,"",E9/D9) | G9: =IF(F9="","",IF(F9>=0.7,3,IF(F9>=0.6,2,IF(F9>=0.5,1,0))))
F10: =IF(D10=0,"",E10/D10) | G10: =IF(F10="","",IF(F10>=0.7,3,IF(F10>=0.6,2,IF(F10>=0.5,1,0))))
F11: =IF(D11=0,"",E11/D11) | G11: =IF(F11="","",IF(F11>=0.7,3,IF(F11>=0.6,2,IF(F11>=0.5,1,0))))
F12: =IF(D12=0,"",E12/D12) | G12: =IF(F12="","",IF(F12>=0.7,3,IF(F12>=0.6,2,IF(F12>=0.5,1,0))))
F13: =IF(D13=0,"",E13/D13) | G13: =IF(F13="","",IF(F13>=0.7,3,IF(F13>=0.6,2,IF(F13>=0.5,1,0))))
F14: =IF(D14=0,"",E14/D14) | G14: =IF(F14="","",IF(F14>=0.7,3,IF(F14>=0.6,2,IF(F14>=0.5,1,0))))
F15: =IF(D15=0,"",E15/D15) | G15: =IF(F15="","",IF(F15>=0.7,3,IF(F15>=0.6,2,IF(F15>=0.5,1,0))))
F16: =IF(D16=0,"",E16/D16) | G16: =IF(F16="","",IF(F16>=0.7,3,IF(F16>=0.6,2,IF(F16>=0.5,1,0))))
F17: =IF(D17=0,"",E17/D17) | G17: =IF(F17="","",IF(F17>=0.7,3,IF(F17>=0.6,2,IF(F17>=0.5,1,0))))
... F202: =IF(D202=0,"",E202/D202) | G202: =IF(F202="","",IF(F202>=0.7,3,IF(F202>=0.6,2,IF(F202>=0.5,1,0))))
A210: Section B: CO-wise Weighted Averages
A211: CO | B211: Avg % Assignment | C211: Avg % UT | D211: Avg % Mid-Term | E211: Weighted Avg % (Auto) | F211: Attainment Level (0–3)
A212: CO1 | E212: =IF(COUNTA(B212:D212)=0,"",B212*'CO Attainment Analysis'!$I$205+C212*'CO Attainment Analysis'!$J$205+D212*'CO Attainment Analysis'!$K$205) | F212: =IF(E212="","",IF(E212>=0.7,3,IF(E212>=0.6,2,IF(E212>=0.5,1,0))))
A213: CO2 | E213: =IF(COUNTA(B213:D213)=0,"",B213*'CO Attainment Analysis'!$I$205+C213*'CO Attainment Analysis'!$J$205+D213*'CO Attainment Analysis'!$K$205) | F213: =IF(E213="","",IF(E213>=0.7,3,IF(E213>=0.6,2,IF(E213>=0.5,1,0))))
A214: CO3 | E214: =IF(COUNTA(B214:D214)=0,"",B214*'CO Attainment Analysis'!$I$205+C214*'CO Attainment Analysis'!$J$205+D214*'CO Attainment Analysis'!$K$205) | F214: =IF(E214="","",IF(E214>=0.7,3,IF(E214>=0.6,2,IF(E214>=0.5,1,0))))
A215: CO4 | E215: =IF(COUNTA(B215:D215)=0,"",B215*'CO Attainment Analysis'!$I$205+C215*'CO Attainment Analysis'!$J$205+D215*'CO Attainment Analysis'!$K$205) | F215: =IF(E215="","",IF(E215>=0.7,3,IF(E215>=0.6,2,IF(E215>=0.5,1,0))))
A230: Section C: CO → PO Aggregation (Weighted by Mapping Strengths)
A231: PO | B231: Contributing COs | C231: Aggregated Attainment (Auto)
A232: PO1 | B232: =TEXTJOIN(", ",TRUE,IF('CO–PO & PSO Matrix'!B$3:B$6<>"",'CO–PO & PSO Matrix'!$A$3:$A$6,"")) | C232: =IF(SUM('CO–PO & PSO Matrix'!B$3:B$6)=0,"",SUMPRODUCT(INDEX('CO Attainment Summary'!$H$3:$H$6, MATCH('CO–PO & PSO Matrix'!$A$3:$A$6, 'CO Attainment Summary'!$A$3:$A$6,0)),'CO–PO & PSO Matrix'!B$3:B$6)/SUM('CO–PO & PSO Matrix'!B$3:B$6))
A233: PO2 | B233: =TEXTJOIN(", ",TRUE,IF('CO–PO & PSO Matrix'!C$3:C$6<>"",'CO–PO & PSO Matrix'!$A$3:$A$6,"")) | C233: =IF(SUM('CO–PO & PSO Matrix'!C$3:C$6)=0,"",SUMPRODUCT(INDEX('CO Attainment Summary'!$H$3:$H$6, MATCH('CO–PO & PSO Matrix'!$A$3:$A$6, 'CO Attainment Summary'!$A$3:$A$6,0)),'CO–PO & PSO Matrix'!C$3:C$6)/SUM('CO–PO & PSO Matrix'!C$3:C$6))
A234: PO3 | B234: =TEXTJOIN(", ",TRUE,IF('CO–PO & PSO Matrix'!D$3:D$6<>"",'CO–PO & PSO Matrix'!$A$3:$A$6,"")) | C234: =IF(SUM('CO–PO & PSO Matrix'!D$3:D$6)=0,"",SUMPRODUCT(INDEX('CO Attainment Summary'!$H$3:$H$6, MATCH('CO–PO & PSO Matrix'!$A$3:$A$6, 'CO Attainment Summary'!$A$3:$A$6,0)),'CO–PO & PSO Matrix'!D$3:D$6)/SUM('CO–PO & PSO Matrix'!D$3:D$6))
A235: PO4 | B235: =TEXTJOIN(", ",TRUE,IF('CO–PO & PSO Matrix'!E$3:E$6<>"",'CO–PO & PSO Matrix'!$A$3:$A$6,"")) | C235: =IF(SUM('CO–PO & PSO Matrix'!E$3:E$6)=0,"",SUMPRODUCT(INDEX('CO Attainment Summary'!$H$3:$H$6, MATCH('CO–PO & PSO Matrix'!$A$3:$A$6, 'CO Attainment Summary'!$A$3:$A$6,0)),'CO–PO & PSO Matrix'!E$3:E$6)/SUM('CO–PO & PSO Matrix'!E$3:E$6))
A236: PO5 | B236: =TEXTJOIN(", ",TRUE,IF('CO–PO & PSO Matrix'!F$3:F$6<>"",'CO–PO & PSO Matrix'!$A$3:$A$6,"")) | C236: =IF(SUM('CO–PO & PSO Matrix'!F$3:F$6)=0,"",SUMPRODUCT(INDEX('CO Attainment Summary'!$H$3:$H$6, MATCH('CO–PO & PSO Matrix'!$A$3:$A$6, 'CO Attainment Summary'!$A$3:$A$6,0)),'CO–PO & PSO Matrix'!F$3:F$6)/SUM('CO–PO & PSO Matrix'!F$3:F$6))
